[2023-11-09T03:59:36.752+0000] {taskinstance.py:1083} INFO - Dependencies all met for <TaskInstance: early_sepsis_prediction.preprocess_train_data manual__2023-11-09T03:59:32.257820+00:00 [queued]>
[2023-11-09T03:59:36.763+0000] {taskinstance.py:1083} INFO - Dependencies all met for <TaskInstance: early_sepsis_prediction.preprocess_train_data manual__2023-11-09T03:59:32.257820+00:00 [queued]>
[2023-11-09T03:59:36.764+0000] {taskinstance.py:1279} INFO - 
--------------------------------------------------------------------------------
[2023-11-09T03:59:36.765+0000] {taskinstance.py:1280} INFO - Starting attempt 1 of 1
[2023-11-09T03:59:36.765+0000] {taskinstance.py:1281} INFO - 
--------------------------------------------------------------------------------
[2023-11-09T03:59:36.779+0000] {taskinstance.py:1300} INFO - Executing <Task(PythonOperator): preprocess_train_data> on 2023-11-09 03:59:32.257820+00:00
[2023-11-09T03:59:36.789+0000] {standard_task_runner.py:55} INFO - Started process 5839 to run task
[2023-11-09T03:59:36.793+0000] {standard_task_runner.py:82} INFO - Running: ['***', 'tasks', 'run', 'early_sepsis_prediction', 'preprocess_train_data', 'manual__2023-11-09T03:59:32.257820+00:00', '--job-id', '231', '--raw', '--subdir', 'DAGS_FOLDER/***.py', '--cfg-path', '/tmp/tmpflwi1xzr']
[2023-11-09T03:59:36.797+0000] {standard_task_runner.py:83} INFO - Job 231: Subtask preprocess_train_data
[2023-11-09T03:59:36.872+0000] {task_command.py:388} INFO - Running <TaskInstance: early_sepsis_prediction.preprocess_train_data manual__2023-11-09T03:59:32.257820+00:00 [running]> on host 4460f47ac51f
[2023-11-09T03:59:36.947+0000] {taskinstance.py:1509} INFO - Exporting the following env vars:
AIRFLOW_CTX_DAG_OWNER=your_name
AIRFLOW_CTX_DAG_ID=early_sepsis_prediction
AIRFLOW_CTX_TASK_ID=preprocess_train_data
AIRFLOW_CTX_EXECUTION_DATE=2023-11-09T03:59:32.257820+00:00
AIRFLOW_CTX_TRY_NUMBER=1
AIRFLOW_CTX_DAG_RUN_ID=manual__2023-11-09T03:59:32.257820+00:00
[2023-11-09T03:59:36.949+0000] {taskinstance.py:1768} ERROR - Task failed with exception
Traceback (most recent call last):
  File "/home/airflow/.local/lib/python3.7/site-packages/airflow/operators/python.py", line 175, in execute
    return_value = self.execute_callable()
  File "/home/airflow/.local/lib/python3.7/site-packages/airflow/operators/python.py", line 192, in execute_callable
    return self.python_callable(*self.op_args, **self.op_kwargs)
  File "/opt/airflow/dags/src/pylab.py", line 40, in preprocess_train_data
    output_param = kwargs['params']['output_param']
KeyError: 'output_param'
[2023-11-09T03:59:36.964+0000] {taskinstance.py:1323} INFO - Marking task as FAILED. dag_id=early_sepsis_prediction, task_id=preprocess_train_data, execution_date=20231109T035932, start_date=20231109T035936, end_date=20231109T035936
[2023-11-09T03:59:36.975+0000] {standard_task_runner.py:105} ERROR - Failed to execute job 231 for task preprocess_train_data ('output_param'; 5839)
[2023-11-09T03:59:37.006+0000] {local_task_job.py:208} INFO - Task exited with return code 1
[2023-11-09T03:59:37.033+0000] {taskinstance.py:2578} INFO - 0 downstream tasks scheduled from follow-on schedule check
