[2023-11-11T03:28:08.117+0000] {taskinstance.py:1083} INFO - Dependencies all met for <TaskInstance: early_sepsis_prediction.feature_engineering manual__2023-11-11T03:26:15.241419+00:00 [queued]>
[2023-11-11T03:28:08.127+0000] {taskinstance.py:1083} INFO - Dependencies all met for <TaskInstance: early_sepsis_prediction.feature_engineering manual__2023-11-11T03:26:15.241419+00:00 [queued]>
[2023-11-11T03:28:08.128+0000] {taskinstance.py:1279} INFO - 
--------------------------------------------------------------------------------
[2023-11-11T03:28:08.129+0000] {taskinstance.py:1280} INFO - Starting attempt 1 of 1
[2023-11-11T03:28:08.129+0000] {taskinstance.py:1281} INFO - 
--------------------------------------------------------------------------------
[2023-11-11T03:28:08.141+0000] {taskinstance.py:1300} INFO - Executing <Task(PythonOperator): feature_engineering> on 2023-11-11 03:26:15.241419+00:00
[2023-11-11T03:28:08.149+0000] {standard_task_runner.py:55} INFO - Started process 8317 to run task
[2023-11-11T03:28:08.154+0000] {standard_task_runner.py:82} INFO - Running: ['***', 'tasks', 'run', 'early_sepsis_prediction', 'feature_engineering', 'manual__2023-11-11T03:26:15.241419+00:00', '--job-id', '347', '--raw', '--subdir', 'DAGS_FOLDER/***.py', '--cfg-path', '/tmp/tmpws851845']
[2023-11-11T03:28:08.157+0000] {standard_task_runner.py:83} INFO - Job 347: Subtask feature_engineering
[2023-11-11T03:28:08.237+0000] {task_command.py:388} INFO - Running <TaskInstance: early_sepsis_prediction.feature_engineering manual__2023-11-11T03:26:15.241419+00:00 [running]> on host 2f30e812c633
[2023-11-11T03:28:08.311+0000] {taskinstance.py:1509} INFO - Exporting the following env vars:
AIRFLOW_CTX_DAG_OWNER=Pavs
AIRFLOW_CTX_DAG_ID=early_sepsis_prediction
AIRFLOW_CTX_TASK_ID=feature_engineering
AIRFLOW_CTX_EXECUTION_DATE=2023-11-11T03:26:15.241419+00:00
AIRFLOW_CTX_TRY_NUMBER=1
AIRFLOW_CTX_DAG_RUN_ID=manual__2023-11-11T03:26:15.241419+00:00
[2023-11-11T03:28:10.370+0000] {taskinstance.py:1768} ERROR - Task failed with exception
Traceback (most recent call last):
  File "/home/airflow/.local/lib/python3.7/site-packages/airflow/operators/python.py", line 175, in execute
    return_value = self.execute_callable()
  File "/home/airflow/.local/lib/python3.7/site-packages/airflow/operators/python.py", line 192, in execute_callable
    return self.python_callable(*self.op_args, **self.op_kwargs)
  File "/opt/airflow/dags/src/pylab1.py", line 102, in feature_engineering
    train_df = train_df[['id','ICULOS', 'Temp', 'Age', 'HR', 'Glucose', 'WBC', 'SBP', 'Platelets', 'Hct', 'PTT', 'MAP', 'Hgb', 'HospAdmTime', 'Resp', 'BUN', 'Phosphate', 'Calcium', 'Creatinine', 'Chloride', 'Potassium', 'PaCO2', 'pH', 'HCO3', 'Lactate', 'DBP', 'Magnesium', 'BaseExcess', 'O2Sat', 'FiO2', 'Alkalinephos', 'AST', 'Bilirubin_total', 'SaO2', 'Fibrinogen']]
  File "/home/airflow/.local/lib/python3.7/site-packages/pandas/core/frame.py", line 3464, in __getitem__
    indexer = self.loc._get_listlike_indexer(key, axis=1)[1]
  File "/home/airflow/.local/lib/python3.7/site-packages/pandas/core/indexing.py", line 1314, in _get_listlike_indexer
    self._validate_read_indexer(keyarr, indexer, axis)
  File "/home/airflow/.local/lib/python3.7/site-packages/pandas/core/indexing.py", line 1377, in _validate_read_indexer
    raise KeyError(f"{not_found} not in index")
KeyError: "['id'] not in index"
[2023-11-11T03:28:10.387+0000] {taskinstance.py:1323} INFO - Marking task as FAILED. dag_id=early_sepsis_prediction, task_id=feature_engineering, execution_date=20231111T032615, start_date=20231111T032808, end_date=20231111T032810
[2023-11-11T03:28:10.402+0000] {standard_task_runner.py:105} ERROR - Failed to execute job 347 for task feature_engineering ("['id'] not in index"; 8317)
[2023-11-11T03:28:10.523+0000] {local_task_job.py:208} INFO - Task exited with return code 1
[2023-11-11T03:28:10.554+0000] {taskinstance.py:2578} INFO - 0 downstream tasks scheduled from follow-on schedule check
