[2023-11-09T03:20:31.101+0000] {taskinstance.py:1083} INFO - Dependencies all met for <TaskInstance: early_sepsis_prediction.preprocess_train_data manual__2023-11-09T03:20:26.721381+00:00 [queued]>
[2023-11-09T03:20:31.111+0000] {taskinstance.py:1083} INFO - Dependencies all met for <TaskInstance: early_sepsis_prediction.preprocess_train_data manual__2023-11-09T03:20:26.721381+00:00 [queued]>
[2023-11-09T03:20:31.112+0000] {taskinstance.py:1279} INFO - 
--------------------------------------------------------------------------------
[2023-11-09T03:20:31.112+0000] {taskinstance.py:1280} INFO - Starting attempt 1 of 1
[2023-11-09T03:20:31.113+0000] {taskinstance.py:1281} INFO - 
--------------------------------------------------------------------------------
[2023-11-09T03:20:31.128+0000] {taskinstance.py:1300} INFO - Executing <Task(PythonOperator): preprocess_train_data> on 2023-11-09 03:20:26.721381+00:00
[2023-11-09T03:20:31.139+0000] {standard_task_runner.py:55} INFO - Started process 3213 to run task
[2023-11-09T03:20:31.148+0000] {standard_task_runner.py:82} INFO - Running: ['***', 'tasks', 'run', 'early_sepsis_prediction', 'preprocess_train_data', 'manual__2023-11-09T03:20:26.721381+00:00', '--job-id', '134', '--raw', '--subdir', 'DAGS_FOLDER/***.py', '--cfg-path', '/tmp/tmpk6kx3kcy']
[2023-11-09T03:20:31.151+0000] {standard_task_runner.py:83} INFO - Job 134: Subtask preprocess_train_data
[2023-11-09T03:20:31.239+0000] {task_command.py:388} INFO - Running <TaskInstance: early_sepsis_prediction.preprocess_train_data manual__2023-11-09T03:20:26.721381+00:00 [running]> on host 4460f47ac51f
[2023-11-09T03:20:31.320+0000] {taskinstance.py:1509} INFO - Exporting the following env vars:
AIRFLOW_CTX_DAG_OWNER=your_name
AIRFLOW_CTX_DAG_ID=early_sepsis_prediction
AIRFLOW_CTX_TASK_ID=preprocess_train_data
AIRFLOW_CTX_EXECUTION_DATE=2023-11-09T03:20:26.721381+00:00
AIRFLOW_CTX_TRY_NUMBER=1
AIRFLOW_CTX_DAG_RUN_ID=manual__2023-11-09T03:20:26.721381+00:00
[2023-11-09T03:20:31.336+0000] {taskinstance.py:1768} ERROR - Task failed with exception
Traceback (most recent call last):
  File "/home/airflow/.local/lib/python3.7/site-packages/airflow/operators/python.py", line 175, in execute
    return_value = self.execute_callable()
  File "/home/airflow/.local/lib/python3.7/site-packages/airflow/operators/python.py", line 192, in execute_callable
    return self.python_callable(*self.op_args, **self.op_kwargs)
  File "/opt/airflow/dags/src/pylab.py", line 39, in preprocess_train_data
    train_data,valid_data,test_data=xcom_value
TypeError: cannot unpack non-iterable NoneType object
[2023-11-09T03:20:31.352+0000] {taskinstance.py:1323} INFO - Marking task as FAILED. dag_id=early_sepsis_prediction, task_id=preprocess_train_data, execution_date=20231109T032026, start_date=20231109T032031, end_date=20231109T032031
[2023-11-09T03:20:31.370+0000] {standard_task_runner.py:105} ERROR - Failed to execute job 134 for task preprocess_train_data (cannot unpack non-iterable NoneType object; 3213)
[2023-11-09T03:20:31.399+0000] {local_task_job.py:208} INFO - Task exited with return code 1
[2023-11-09T03:20:31.425+0000] {taskinstance.py:2578} INFO - 0 downstream tasks scheduled from follow-on schedule check
